[2023-04-12T06:51:48.361+0000] {taskinstance.py:1090} INFO - Dependencies all met for dep_context=non-requeueable deps ti=<TaskInstance: data_extraction_dag.task_teams manual__2023-04-12T05:46:33.697967+00:00 [queued]>
[2023-04-12T06:51:48.375+0000] {taskinstance.py:1090} INFO - Dependencies all met for dep_context=requeueable deps ti=<TaskInstance: data_extraction_dag.task_teams manual__2023-04-12T05:46:33.697967+00:00 [queued]>
[2023-04-12T06:51:48.376+0000] {taskinstance.py:1288} INFO - 
--------------------------------------------------------------------------------
[2023-04-12T06:51:48.377+0000] {taskinstance.py:1289} INFO - Starting attempt 7 of 8
[2023-04-12T06:51:48.377+0000] {taskinstance.py:1290} INFO - 
--------------------------------------------------------------------------------
[2023-04-12T06:51:48.396+0000] {taskinstance.py:1309} INFO - Executing <Task(_PythonDecoratedOperator): task_teams> on 2023-04-12 05:46:33.697967+00:00
[2023-04-12T06:51:48.398+0000] {taskinstance.py:1080} INFO - Dependencies not met for <TaskInstance: data_extraction_dag.task_teams manual__2023-04-12T05:46:33.697967+00:00 [running]>, dependency 'Task Instance State' FAILED: Task is in the 'running' state.
[2023-04-12T06:51:48.399+0000] {taskinstance.py:1080} INFO - Dependencies not met for <TaskInstance: data_extraction_dag.task_teams manual__2023-04-12T05:46:33.697967+00:00 [running]>, dependency 'Task Instance Not Running' FAILED: Task is in the running state
[2023-04-12T06:51:48.406+0000] {standard_task_runner.py:55} INFO - Started process 2839 to run task
[2023-04-12T06:51:48.409+0000] {standard_task_runner.py:82} INFO - Running: ['***', 'tasks', 'run', 'data_extraction_dag', 'task_teams', 'manual__2023-04-12T05:46:33.697967+00:00', '--job-id', '472', '--pool', 'default_pool', '--raw', '--subdir', 'DAGS_FOLDER/data_ingestion.py', '--cfg-path', '/tmp/tmpk5pcv64m']
[2023-04-12T06:51:48.413+0000] {standard_task_runner.py:83} INFO - Job 472: Subtask task_teams
[2023-04-12T06:51:48.413+0000] {local_task_job.py:151} INFO - Task is not able to be run
[2023-04-12T06:51:48.496+0000] {task_command.py:389} INFO - Running <TaskInstance: data_extraction_dag.task_teams manual__2023-04-12T05:46:33.697967+00:00 [running]> on host a073412e57f0
[2023-04-12T06:51:48.577+0000] {taskinstance.py:1516} INFO - Exporting the following env vars:
AIRFLOW_CTX_DAG_OWNER=***
AIRFLOW_CTX_DAG_ID=data_extraction_dag
AIRFLOW_CTX_TASK_ID=task_teams
AIRFLOW_CTX_EXECUTION_DATE=2023-04-12T05:46:33.697967+00:00
AIRFLOW_CTX_TRY_NUMBER=7
AIRFLOW_CTX_DAG_RUN_ID=manual__2023-04-12T05:46:33.697967+00:00
[2023-04-12T06:51:48.580+0000] {logging_mixin.py:137} INFO - Fetching for teams started
[2023-04-12T06:51:49.537+0000] {logging_mixin.py:137} INFO - Fetching for teams ended
[2023-04-12T06:51:49.538+0000] {logging_mixin.py:137} INFO - Loading for nfl data to parquet started
[2023-04-12T06:51:49.686+0000] {_metadata.py:154} WARNING - Compute Engine Metadata server unavailable on attempt 1 of 5. Reason: HTTPConnectionPool(host='metadata.google.internal', port=80): Max retries exceeded with url: /computeMetadata/v1/instance/service-accounts/default/?recursive=true (Caused by NewConnectionError('<urllib3.connection.HTTPConnection object at 0x7fd310603ac0>: Failed to establish a new connection: [Errno -2] Name or service not known'))
[2023-04-12T06:51:49.694+0000] {_metadata.py:154} WARNING - Compute Engine Metadata server unavailable on attempt 2 of 5. Reason: HTTPConnectionPool(host='metadata.google.internal', port=80): Max retries exceeded with url: /computeMetadata/v1/instance/service-accounts/default/?recursive=true (Caused by NewConnectionError('<urllib3.connection.HTTPConnection object at 0x7fd310603e20>: Failed to establish a new connection: [Errno -2] Name or service not known'))
[2023-04-12T06:51:49.701+0000] {_metadata.py:154} WARNING - Compute Engine Metadata server unavailable on attempt 3 of 5. Reason: HTTPConnectionPool(host='metadata.google.internal', port=80): Max retries exceeded with url: /computeMetadata/v1/instance/service-accounts/default/?recursive=true (Caused by NewConnectionError('<urllib3.connection.HTTPConnection object at 0x7fd310665400>: Failed to establish a new connection: [Errno -2] Name or service not known'))
[2023-04-12T06:51:49.708+0000] {_metadata.py:154} WARNING - Compute Engine Metadata server unavailable on attempt 4 of 5. Reason: HTTPConnectionPool(host='metadata.google.internal', port=80): Max retries exceeded with url: /computeMetadata/v1/instance/service-accounts/default/?recursive=true (Caused by NewConnectionError('<urllib3.connection.HTTPConnection object at 0x7fd310665880>: Failed to establish a new connection: [Errno -2] Name or service not known'))
[2023-04-12T06:51:49.715+0000] {_metadata.py:154} WARNING - Compute Engine Metadata server unavailable on attempt 5 of 5. Reason: HTTPConnectionPool(host='metadata.google.internal', port=80): Max retries exceeded with url: /computeMetadata/v1/instance/service-accounts/default/?recursive=true (Caused by NewConnectionError('<urllib3.connection.HTTPConnection object at 0x7fd310603f10>: Failed to establish a new connection: [Errno -2] Name or service not known'))
[2023-04-12T06:51:51.144+0000] {retry.py:148} ERROR - _request non-retriable exception: Anonymous caller does not have storage.objects.create access to the Google Cloud Storage object. Permission 'storage.objects.create' denied on resource (or it may not exist)., 401
Traceback (most recent call last):
  File "/home/airflow/.local/lib/python3.9/site-packages/gcsfs/retry.py", line 114, in retry_request
    return await func(*args, **kwargs)
  File "/home/airflow/.local/lib/python3.9/site-packages/gcsfs/core.py", line 411, in _request
    validate_response(status, contents, path, args)
  File "/home/airflow/.local/lib/python3.9/site-packages/gcsfs/retry.py", line 101, in validate_response
    raise HttpError(error)
gcsfs.retry.HttpError: Anonymous caller does not have storage.objects.create access to the Google Cloud Storage object. Permission 'storage.objects.create' denied on resource (or it may not exist)., 401
[2023-04-12T06:51:51.149+0000] {taskinstance.py:1776} ERROR - Task failed with exception
Traceback (most recent call last):
  File "/home/airflow/.local/lib/python3.9/site-packages/airflow/decorators/base.py", line 217, in execute
    return_value = super().execute(context)
  File "/home/airflow/.local/lib/python3.9/site-packages/airflow/operators/python.py", line 175, in execute
    return_value = self.execute_callable()
  File "/home/airflow/.local/lib/python3.9/site-packages/airflow/operators/python.py", line 192, in execute_callable
    return self.python_callable(*self.op_args, **self.op_kwargs)
  File "/opt/airflow/dags/data_ingestion.py", line 115, in task_teams
    teams.to_parquet(f'{path}/nfl_parquets/{year}/{season_type}/teams_parquet', engine='pyarrow')
  File "/home/airflow/.local/lib/python3.9/site-packages/pandas/util/_decorators.py", line 211, in wrapper
    return func(*args, **kwargs)
  File "/home/airflow/.local/lib/python3.9/site-packages/pandas/core/frame.py", line 2976, in to_parquet
    return to_parquet(
  File "/home/airflow/.local/lib/python3.9/site-packages/pandas/io/parquet.py", line 430, in to_parquet
    impl.write(
  File "/home/airflow/.local/lib/python3.9/site-packages/pandas/io/parquet.py", line 204, in write
    self.api.parquet.write_table(
  File "/home/airflow/.local/lib/python3.9/site-packages/pyarrow/parquet/core.py", line 2985, in write_table
    writer.write_table(table, row_group_size=row_group_size)
  File "/home/airflow/.local/lib/python3.9/site-packages/pyarrow/parquet/core.py", line 993, in __exit__
    self.close()
  File "/home/airflow/.local/lib/python3.9/site-packages/pyarrow/parquet/core.py", line 1066, in close
    self.file_handle.close()
  File "pyarrow/io.pxi", line 189, in pyarrow.lib.NativeFile.close
  File "/home/airflow/.local/lib/python3.9/site-packages/fsspec/spec.py", line 1789, in close
    self.flush(force=True)
  File "/home/airflow/.local/lib/python3.9/site-packages/fsspec/spec.py", line 1655, in flush
    self._initiate_upload()
  File "/home/airflow/.local/lib/python3.9/site-packages/gcsfs/core.py", line 1592, in _initiate_upload
    self.location = sync(
  File "/home/airflow/.local/lib/python3.9/site-packages/fsspec/asyn.py", line 100, in sync
    raise return_result
  File "/home/airflow/.local/lib/python3.9/site-packages/fsspec/asyn.py", line 55, in _runner
    result[0] = await coro
  File "/home/airflow/.local/lib/python3.9/site-packages/gcsfs/core.py", line 1708, in initiate_upload
    headers, _ = await fs._call(
  File "/home/airflow/.local/lib/python3.9/site-packages/gcsfs/core.py", line 418, in _call
    status, headers, info, contents = await self._request(
  File "/home/airflow/.local/lib/python3.9/site-packages/decorator.py", line 221, in fun
    return await caller(func, *(extras + args), **kw)
  File "/home/airflow/.local/lib/python3.9/site-packages/gcsfs/retry.py", line 149, in retry_request
    raise e
  File "/home/airflow/.local/lib/python3.9/site-packages/gcsfs/retry.py", line 114, in retry_request
    return await func(*args, **kwargs)
  File "/home/airflow/.local/lib/python3.9/site-packages/gcsfs/core.py", line 411, in _request
    validate_response(status, contents, path, args)
  File "/home/airflow/.local/lib/python3.9/site-packages/gcsfs/retry.py", line 101, in validate_response
    raise HttpError(error)
gcsfs.retry.HttpError: Anonymous caller does not have storage.objects.create access to the Google Cloud Storage object. Permission 'storage.objects.create' denied on resource (or it may not exist)., 401
[2023-04-12T06:51:51.250+0000] {taskinstance.py:1327} INFO - Marking task as UP_FOR_RETRY. dag_id=data_extraction_dag, task_id=task_teams, execution_date=20230412T054633, start_date=20230412T065148, end_date=20230412T065151
[2023-04-12T06:51:51.281+0000] {standard_task_runner.py:100} ERROR - Failed to execute job 472 for task task_teams (Anonymous caller does not have storage.objects.create access to the Google Cloud Storage object. Permission 'storage.objects.create' denied on resource (or it may not exist)., 401; 2839)
[2023-04-12T06:51:51.318+0000] {local_task_job.py:212} INFO - Task exited with return code 1
[2023-04-12T06:51:51.345+0000] {taskinstance.py:2596} INFO - 0 downstream tasks scheduled from follow-on schedule check
