[2023-04-12T06:47:15.038+0000] {taskinstance.py:1080} INFO - Dependencies not met for <TaskInstance: data_extraction_dag.task_teams manual__2023-04-12T05:46:33.697967+00:00 [up_for_retry]>, dependency 'Not In Retry Period' FAILED: Task is not ready for retry yet but will be retried automatically. Current date is 2023-04-12T06:47:15.038380+00:00 and task will be retried at 2023-04-12T06:52:14.323942+00:00.
[2023-04-12T06:47:15.051+0000] {local_task_job.py:151} INFO - Task is not able to be run
[2023-04-12T06:47:48.776+0000] {taskinstance.py:1090} INFO - Dependencies all met for dep_context=non-requeueable deps ti=<TaskInstance: data_extraction_dag.task_teams manual__2023-04-12T05:46:33.697967+00:00 [queued]>
[2023-04-12T06:47:48.790+0000] {taskinstance.py:1090} INFO - Dependencies all met for dep_context=requeueable deps ti=<TaskInstance: data_extraction_dag.task_teams manual__2023-04-12T05:46:33.697967+00:00 [queued]>
[2023-04-12T06:47:48.790+0000] {taskinstance.py:1288} INFO - 
--------------------------------------------------------------------------------
[2023-04-12T06:47:48.792+0000] {taskinstance.py:1289} INFO - Starting attempt 6 of 7
[2023-04-12T06:47:48.792+0000] {taskinstance.py:1290} INFO - 
--------------------------------------------------------------------------------
[2023-04-12T06:47:48.817+0000] {taskinstance.py:1309} INFO - Executing <Task(_PythonDecoratedOperator): task_teams> on 2023-04-12 05:46:33.697967+00:00
[2023-04-12T06:47:48.825+0000] {standard_task_runner.py:55} INFO - Started process 2609 to run task
[2023-04-12T06:47:48.830+0000] {standard_task_runner.py:82} INFO - Running: ['***', 'tasks', 'run', 'data_extraction_dag', 'task_teams', 'manual__2023-04-12T05:46:33.697967+00:00', '--job-id', '470', '--raw', '--subdir', 'DAGS_FOLDER/data_ingestion.py', '--cfg-path', '/tmp/tmp9z7iq095']
[2023-04-12T06:47:48.833+0000] {standard_task_runner.py:83} INFO - Job 470: Subtask task_teams
[2023-04-12T06:47:48.910+0000] {task_command.py:389} INFO - Running <TaskInstance: data_extraction_dag.task_teams manual__2023-04-12T05:46:33.697967+00:00 [running]> on host a073412e57f0
[2023-04-12T06:47:48.989+0000] {taskinstance.py:1516} INFO - Exporting the following env vars:
AIRFLOW_CTX_DAG_OWNER=***
AIRFLOW_CTX_DAG_ID=data_extraction_dag
AIRFLOW_CTX_TASK_ID=task_teams
AIRFLOW_CTX_EXECUTION_DATE=2023-04-12T05:46:33.697967+00:00
AIRFLOW_CTX_TRY_NUMBER=6
AIRFLOW_CTX_DAG_RUN_ID=manual__2023-04-12T05:46:33.697967+00:00
[2023-04-12T06:47:48.992+0000] {logging_mixin.py:137} INFO - Fetching for teams started
[2023-04-12T06:47:49.832+0000] {logging_mixin.py:137} INFO - Fetching for teams ended
[2023-04-12T06:47:49.833+0000] {logging_mixin.py:137} INFO - Loading for nfl data to parquet started
[2023-04-12T06:47:50.038+0000] {_metadata.py:154} WARNING - Compute Engine Metadata server unavailable on attempt 1 of 5. Reason: HTTPConnectionPool(host='metadata.google.internal', port=80): Max retries exceeded with url: /computeMetadata/v1/instance/service-accounts/default/?recursive=true (Caused by NewConnectionError('<urllib3.connection.HTTPConnection object at 0x7fd3106005e0>: Failed to establish a new connection: [Errno -2] Name or service not known'))
[2023-04-12T06:47:50.045+0000] {_metadata.py:154} WARNING - Compute Engine Metadata server unavailable on attempt 2 of 5. Reason: HTTPConnectionPool(host='metadata.google.internal', port=80): Max retries exceeded with url: /computeMetadata/v1/instance/service-accounts/default/?recursive=true (Caused by NewConnectionError('<urllib3.connection.HTTPConnection object at 0x7fd310600370>: Failed to establish a new connection: [Errno -2] Name or service not known'))
[2023-04-12T06:47:50.051+0000] {_metadata.py:154} WARNING - Compute Engine Metadata server unavailable on attempt 3 of 5. Reason: HTTPConnectionPool(host='metadata.google.internal', port=80): Max retries exceeded with url: /computeMetadata/v1/instance/service-accounts/default/?recursive=true (Caused by NewConnectionError('<urllib3.connection.HTTPConnection object at 0x7fd310600f10>: Failed to establish a new connection: [Errno -2] Name or service not known'))
[2023-04-12T06:47:50.059+0000] {_metadata.py:154} WARNING - Compute Engine Metadata server unavailable on attempt 4 of 5. Reason: HTTPConnectionPool(host='metadata.google.internal', port=80): Max retries exceeded with url: /computeMetadata/v1/instance/service-accounts/default/?recursive=true (Caused by NewConnectionError('<urllib3.connection.HTTPConnection object at 0x7fd3106002e0>: Failed to establish a new connection: [Errno -2] Name or service not known'))
[2023-04-12T06:47:50.066+0000] {_metadata.py:154} WARNING - Compute Engine Metadata server unavailable on attempt 5 of 5. Reason: HTTPConnectionPool(host='metadata.google.internal', port=80): Max retries exceeded with url: /computeMetadata/v1/instance/service-accounts/default/?recursive=true (Caused by NewConnectionError('<urllib3.connection.HTTPConnection object at 0x7fd310600070>: Failed to establish a new connection: [Errno -2] Name or service not known'))
[2023-04-12T06:47:50.452+0000] {taskinstance.py:1090} INFO - Dependencies all met for dep_context=non-requeueable deps ti=<TaskInstance: data_extraction_dag.task_teams manual__2023-04-12T05:46:33.697967+00:00 [queued]>
[2023-04-12T06:47:50.464+0000] {taskinstance.py:1090} INFO - Dependencies all met for dep_context=requeueable deps ti=<TaskInstance: data_extraction_dag.task_teams manual__2023-04-12T05:46:33.697967+00:00 [queued]>
[2023-04-12T06:47:50.465+0000] {taskinstance.py:1288} INFO - 
--------------------------------------------------------------------------------
[2023-04-12T06:47:50.466+0000] {taskinstance.py:1289} INFO - Starting attempt 6 of 7
[2023-04-12T06:47:50.467+0000] {taskinstance.py:1290} INFO - 
--------------------------------------------------------------------------------
[2023-04-12T06:47:50.486+0000] {taskinstance.py:1309} INFO - Executing <Task(_PythonDecoratedOperator): task_teams> on 2023-04-12 05:46:33.697967+00:00
[2023-04-12T06:47:50.498+0000] {standard_task_runner.py:55} INFO - Started process 2646 to run task
[2023-04-12T06:47:50.502+0000] {standard_task_runner.py:82} INFO - Running: ['***', 'tasks', 'run', 'data_extraction_dag', 'task_teams', 'manual__2023-04-12T05:46:33.697967+00:00', '--job-id', '471', '--pool', 'default_pool', '--raw', '--subdir', 'DAGS_FOLDER/data_ingestion.py', '--cfg-path', '/tmp/tmpepv9ra8b']
[2023-04-12T06:47:50.506+0000] {standard_task_runner.py:83} INFO - Job 471: Subtask task_teams
[2023-04-12T06:47:50.588+0000] {task_command.py:389} INFO - Running <TaskInstance: data_extraction_dag.task_teams manual__2023-04-12T05:46:33.697967+00:00 [running]> on host a073412e57f0
[2023-04-12T06:47:50.659+0000] {taskinstance.py:1516} INFO - Exporting the following env vars:
AIRFLOW_CTX_DAG_OWNER=***
AIRFLOW_CTX_DAG_ID=data_extraction_dag
AIRFLOW_CTX_TASK_ID=task_teams
AIRFLOW_CTX_EXECUTION_DATE=2023-04-12T05:46:33.697967+00:00
AIRFLOW_CTX_TRY_NUMBER=6
AIRFLOW_CTX_DAG_RUN_ID=manual__2023-04-12T05:46:33.697967+00:00
[2023-04-12T06:47:50.663+0000] {logging_mixin.py:137} INFO - Fetching for teams started
[2023-04-12T06:47:51.289+0000] {logging_mixin.py:137} INFO - Fetching for teams ended
[2023-04-12T06:47:51.290+0000] {logging_mixin.py:137} INFO - Loading for nfl data to parquet started
[2023-04-12T06:47:51.381+0000] {_metadata.py:154} WARNING - Compute Engine Metadata server unavailable on attempt 1 of 5. Reason: HTTPConnectionPool(host='metadata.google.internal', port=80): Max retries exceeded with url: /computeMetadata/v1/instance/service-accounts/default/?recursive=true (Caused by NewConnectionError('<urllib3.connection.HTTPConnection object at 0x7fd310678be0>: Failed to establish a new connection: [Errno -2] Name or service not known'))
[2023-04-12T06:47:51.390+0000] {_metadata.py:154} WARNING - Compute Engine Metadata server unavailable on attempt 2 of 5. Reason: HTTPConnectionPool(host='metadata.google.internal', port=80): Max retries exceeded with url: /computeMetadata/v1/instance/service-accounts/default/?recursive=true (Caused by NewConnectionError('<urllib3.connection.HTTPConnection object at 0x7fd310678f40>: Failed to establish a new connection: [Errno -2] Name or service not known'))
[2023-04-12T06:47:51.398+0000] {_metadata.py:154} WARNING - Compute Engine Metadata server unavailable on attempt 3 of 5. Reason: HTTPConnectionPool(host='metadata.google.internal', port=80): Max retries exceeded with url: /computeMetadata/v1/instance/service-accounts/default/?recursive=true (Caused by NewConnectionError('<urllib3.connection.HTTPConnection object at 0x7fd31064c340>: Failed to establish a new connection: [Errno -2] Name or service not known'))
[2023-04-12T06:47:51.407+0000] {_metadata.py:154} WARNING - Compute Engine Metadata server unavailable on attempt 4 of 5. Reason: HTTPConnectionPool(host='metadata.google.internal', port=80): Max retries exceeded with url: /computeMetadata/v1/instance/service-accounts/default/?recursive=true (Caused by NewConnectionError('<urllib3.connection.HTTPConnection object at 0x7fd310678fa0>: Failed to establish a new connection: [Errno -2] Name or service not known'))
[2023-04-12T06:47:51.415+0000] {_metadata.py:154} WARNING - Compute Engine Metadata server unavailable on attempt 5 of 5. Reason: HTTPConnectionPool(host='metadata.google.internal', port=80): Max retries exceeded with url: /computeMetadata/v1/instance/service-accounts/default/?recursive=true (Caused by NewConnectionError('<urllib3.connection.HTTPConnection object at 0x7fd31064c130>: Failed to establish a new connection: [Errno -2] Name or service not known'))
[2023-04-12T06:47:51.552+0000] {retry.py:148} ERROR - _request non-retriable exception: Anonymous caller does not have storage.objects.create access to the Google Cloud Storage object. Permission 'storage.objects.create' denied on resource (or it may not exist)., 401
Traceback (most recent call last):
  File "/home/airflow/.local/lib/python3.9/site-packages/gcsfs/retry.py", line 114, in retry_request
    return await func(*args, **kwargs)
  File "/home/airflow/.local/lib/python3.9/site-packages/gcsfs/core.py", line 411, in _request
    validate_response(status, contents, path, args)
  File "/home/airflow/.local/lib/python3.9/site-packages/gcsfs/retry.py", line 101, in validate_response
    raise HttpError(error)
gcsfs.retry.HttpError: Anonymous caller does not have storage.objects.create access to the Google Cloud Storage object. Permission 'storage.objects.create' denied on resource (or it may not exist)., 401
[2023-04-12T06:47:51.558+0000] {taskinstance.py:1776} ERROR - Task failed with exception
Traceback (most recent call last):
  File "/home/airflow/.local/lib/python3.9/site-packages/airflow/decorators/base.py", line 217, in execute
    return_value = super().execute(context)
  File "/home/airflow/.local/lib/python3.9/site-packages/airflow/operators/python.py", line 175, in execute
    return_value = self.execute_callable()
  File "/home/airflow/.local/lib/python3.9/site-packages/airflow/operators/python.py", line 192, in execute_callable
    return self.python_callable(*self.op_args, **self.op_kwargs)
  File "/opt/airflow/dags/data_ingestion.py", line 115, in task_teams
    teams.to_parquet(f'{path}/nfl_parquets/{year}/{season_type}/teams_parquet', engine='pyarrow')
  File "/home/airflow/.local/lib/python3.9/site-packages/pandas/util/_decorators.py", line 211, in wrapper
    return func(*args, **kwargs)
  File "/home/airflow/.local/lib/python3.9/site-packages/pandas/core/frame.py", line 2976, in to_parquet
    return to_parquet(
  File "/home/airflow/.local/lib/python3.9/site-packages/pandas/io/parquet.py", line 430, in to_parquet
    impl.write(
  File "/home/airflow/.local/lib/python3.9/site-packages/pandas/io/parquet.py", line 204, in write
    self.api.parquet.write_table(
  File "/home/airflow/.local/lib/python3.9/site-packages/pyarrow/parquet/core.py", line 2985, in write_table
    writer.write_table(table, row_group_size=row_group_size)
  File "/home/airflow/.local/lib/python3.9/site-packages/pyarrow/parquet/core.py", line 993, in __exit__
    self.close()
  File "/home/airflow/.local/lib/python3.9/site-packages/pyarrow/parquet/core.py", line 1066, in close
    self.file_handle.close()
  File "pyarrow/io.pxi", line 189, in pyarrow.lib.NativeFile.close
  File "/home/airflow/.local/lib/python3.9/site-packages/fsspec/spec.py", line 1789, in close
    self.flush(force=True)
  File "/home/airflow/.local/lib/python3.9/site-packages/fsspec/spec.py", line 1655, in flush
    self._initiate_upload()
  File "/home/airflow/.local/lib/python3.9/site-packages/gcsfs/core.py", line 1592, in _initiate_upload
    self.location = sync(
  File "/home/airflow/.local/lib/python3.9/site-packages/fsspec/asyn.py", line 100, in sync
    raise return_result
  File "/home/airflow/.local/lib/python3.9/site-packages/fsspec/asyn.py", line 55, in _runner
    result[0] = await coro
  File "/home/airflow/.local/lib/python3.9/site-packages/gcsfs/core.py", line 1708, in initiate_upload
    headers, _ = await fs._call(
  File "/home/airflow/.local/lib/python3.9/site-packages/gcsfs/core.py", line 418, in _call
    status, headers, info, contents = await self._request(
  File "/home/airflow/.local/lib/python3.9/site-packages/decorator.py", line 221, in fun
    return await caller(func, *(extras + args), **kw)
  File "/home/airflow/.local/lib/python3.9/site-packages/gcsfs/retry.py", line 149, in retry_request
    raise e
  File "/home/airflow/.local/lib/python3.9/site-packages/gcsfs/retry.py", line 114, in retry_request
    return await func(*args, **kwargs)
  File "/home/airflow/.local/lib/python3.9/site-packages/gcsfs/core.py", line 411, in _request
    validate_response(status, contents, path, args)
  File "/home/airflow/.local/lib/python3.9/site-packages/gcsfs/retry.py", line 101, in validate_response
    raise HttpError(error)
gcsfs.retry.HttpError: Anonymous caller does not have storage.objects.create access to the Google Cloud Storage object. Permission 'storage.objects.create' denied on resource (or it may not exist)., 401
[2023-04-12T06:47:51.599+0000] {taskinstance.py:1327} INFO - Marking task as UP_FOR_RETRY. dag_id=data_extraction_dag, task_id=task_teams, execution_date=20230412T054633, start_date=20230412T064750, end_date=20230412T064751
[2023-04-12T06:47:51.617+0000] {standard_task_runner.py:100} ERROR - Failed to execute job 470 for task task_teams (Anonymous caller does not have storage.objects.create access to the Google Cloud Storage object. Permission 'storage.objects.create' denied on resource (or it may not exist)., 401; 2609)
[2023-04-12T06:47:51.657+0000] {local_task_job.py:212} INFO - Task exited with return code 1
[2023-04-12T06:47:51.681+0000] {taskinstance.py:2596} INFO - 0 downstream tasks scheduled from follow-on schedule check
[2023-04-12T06:47:52.712+0000] {retry.py:148} ERROR - _request non-retriable exception: Anonymous caller does not have storage.objects.create access to the Google Cloud Storage object. Permission 'storage.objects.create' denied on resource (or it may not exist)., 401
Traceback (most recent call last):
  File "/home/airflow/.local/lib/python3.9/site-packages/gcsfs/retry.py", line 114, in retry_request
    return await func(*args, **kwargs)
  File "/home/airflow/.local/lib/python3.9/site-packages/gcsfs/core.py", line 411, in _request
    validate_response(status, contents, path, args)
  File "/home/airflow/.local/lib/python3.9/site-packages/gcsfs/retry.py", line 101, in validate_response
    raise HttpError(error)
gcsfs.retry.HttpError: Anonymous caller does not have storage.objects.create access to the Google Cloud Storage object. Permission 'storage.objects.create' denied on resource (or it may not exist)., 401
[2023-04-12T06:47:52.714+0000] {taskinstance.py:1776} ERROR - Task failed with exception
Traceback (most recent call last):
  File "/home/airflow/.local/lib/python3.9/site-packages/airflow/decorators/base.py", line 217, in execute
    return_value = super().execute(context)
  File "/home/airflow/.local/lib/python3.9/site-packages/airflow/operators/python.py", line 175, in execute
    return_value = self.execute_callable()
  File "/home/airflow/.local/lib/python3.9/site-packages/airflow/operators/python.py", line 192, in execute_callable
    return self.python_callable(*self.op_args, **self.op_kwargs)
  File "/opt/airflow/dags/data_ingestion.py", line 115, in task_teams
    teams.to_parquet(f'{path}/nfl_parquets/{year}/{season_type}/teams_parquet', engine='pyarrow')
  File "/home/airflow/.local/lib/python3.9/site-packages/pandas/util/_decorators.py", line 211, in wrapper
    return func(*args, **kwargs)
  File "/home/airflow/.local/lib/python3.9/site-packages/pandas/core/frame.py", line 2976, in to_parquet
    return to_parquet(
  File "/home/airflow/.local/lib/python3.9/site-packages/pandas/io/parquet.py", line 430, in to_parquet
    impl.write(
  File "/home/airflow/.local/lib/python3.9/site-packages/pandas/io/parquet.py", line 204, in write
    self.api.parquet.write_table(
  File "/home/airflow/.local/lib/python3.9/site-packages/pyarrow/parquet/core.py", line 2985, in write_table
    writer.write_table(table, row_group_size=row_group_size)
  File "/home/airflow/.local/lib/python3.9/site-packages/pyarrow/parquet/core.py", line 993, in __exit__
    self.close()
  File "/home/airflow/.local/lib/python3.9/site-packages/pyarrow/parquet/core.py", line 1066, in close
    self.file_handle.close()
  File "pyarrow/io.pxi", line 189, in pyarrow.lib.NativeFile.close
  File "/home/airflow/.local/lib/python3.9/site-packages/fsspec/spec.py", line 1789, in close
    self.flush(force=True)
  File "/home/airflow/.local/lib/python3.9/site-packages/fsspec/spec.py", line 1655, in flush
    self._initiate_upload()
  File "/home/airflow/.local/lib/python3.9/site-packages/gcsfs/core.py", line 1592, in _initiate_upload
    self.location = sync(
  File "/home/airflow/.local/lib/python3.9/site-packages/fsspec/asyn.py", line 100, in sync
    raise return_result
  File "/home/airflow/.local/lib/python3.9/site-packages/fsspec/asyn.py", line 55, in _runner
    result[0] = await coro
  File "/home/airflow/.local/lib/python3.9/site-packages/gcsfs/core.py", line 1708, in initiate_upload
    headers, _ = await fs._call(
  File "/home/airflow/.local/lib/python3.9/site-packages/gcsfs/core.py", line 418, in _call
    status, headers, info, contents = await self._request(
  File "/home/airflow/.local/lib/python3.9/site-packages/decorator.py", line 221, in fun
    return await caller(func, *(extras + args), **kw)
  File "/home/airflow/.local/lib/python3.9/site-packages/gcsfs/retry.py", line 149, in retry_request
    raise e
  File "/home/airflow/.local/lib/python3.9/site-packages/gcsfs/retry.py", line 114, in retry_request
    return await func(*args, **kwargs)
  File "/home/airflow/.local/lib/python3.9/site-packages/gcsfs/core.py", line 411, in _request
    validate_response(status, contents, path, args)
  File "/home/airflow/.local/lib/python3.9/site-packages/gcsfs/retry.py", line 101, in validate_response
    raise HttpError(error)
gcsfs.retry.HttpError: Anonymous caller does not have storage.objects.create access to the Google Cloud Storage object. Permission 'storage.objects.create' denied on resource (or it may not exist)., 401
[2023-04-12T06:47:52.827+0000] {taskinstance.py:1327} INFO - Marking task as FAILED. dag_id=data_extraction_dag, task_id=task_teams, execution_date=20230412T054633, start_date=20230412T064750, end_date=20230412T064752
[2023-04-12T06:47:52.845+0000] {standard_task_runner.py:100} ERROR - Failed to execute job 471 for task task_teams (Anonymous caller does not have storage.objects.create access to the Google Cloud Storage object. Permission 'storage.objects.create' denied on resource (or it may not exist)., 401; 2646)
[2023-04-12T06:47:52.888+0000] {local_task_job.py:212} INFO - Task exited with return code 1
[2023-04-12T06:47:52.916+0000] {taskinstance.py:2596} INFO - 0 downstream tasks scheduled from follow-on schedule check
