[2023-04-12T09:28:43.771+0000] {taskinstance.py:1090} INFO - Dependencies all met for dep_context=non-requeueable deps ti=<TaskInstance: data_extraction_dag.upload_positions_to_gcs manual__2023-04-12T09:16:47.753380+00:00 [queued]>
[2023-04-12T09:28:43.786+0000] {taskinstance.py:1090} INFO - Dependencies all met for dep_context=requeueable deps ti=<TaskInstance: data_extraction_dag.upload_positions_to_gcs manual__2023-04-12T09:16:47.753380+00:00 [queued]>
[2023-04-12T09:28:43.787+0000] {taskinstance.py:1288} INFO - 
--------------------------------------------------------------------------------
[2023-04-12T09:28:43.787+0000] {taskinstance.py:1289} INFO - Starting attempt 6 of 7
[2023-04-12T09:28:43.788+0000] {taskinstance.py:1290} INFO - 
--------------------------------------------------------------------------------
[2023-04-12T09:28:43.810+0000] {taskinstance.py:1309} INFO - Executing <Task(_PythonDecoratedOperator): upload_positions_to_gcs> on 2023-04-12 09:16:47.753380+00:00
[2023-04-12T09:28:43.816+0000] {taskinstance.py:1080} INFO - Dependencies not met for <TaskInstance: data_extraction_dag.upload_positions_to_gcs manual__2023-04-12T09:16:47.753380+00:00 [running]>, dependency 'Task Instance State' FAILED: Task is in the 'running' state.
[2023-04-12T09:28:43.826+0000] {taskinstance.py:1080} INFO - Dependencies not met for <TaskInstance: data_extraction_dag.upload_positions_to_gcs manual__2023-04-12T09:16:47.753380+00:00 [running]>, dependency 'Task Instance Not Running' FAILED: Task is in the running state
[2023-04-12T09:28:43.824+0000] {standard_task_runner.py:55} INFO - Started process 5979 to run task
[2023-04-12T09:28:43.831+0000] {local_task_job.py:151} INFO - Task is not able to be run
[2023-04-12T09:28:43.835+0000] {standard_task_runner.py:82} INFO - Running: ['***', 'tasks', 'run', 'data_extraction_dag', 'upload_positions_to_gcs', 'manual__2023-04-12T09:16:47.753380+00:00', '--job-id', '707', '--raw', '--subdir', 'DAGS_FOLDER/data_ingestion.py', '--cfg-path', '/tmp/tmpsw9zrnv0']
[2023-04-12T09:28:43.841+0000] {standard_task_runner.py:83} INFO - Job 707: Subtask upload_positions_to_gcs
[2023-04-12T09:28:43.937+0000] {task_command.py:389} INFO - Running <TaskInstance: data_extraction_dag.upload_positions_to_gcs manual__2023-04-12T09:16:47.753380+00:00 [running]> on host a2e619923d04
[2023-04-12T09:28:44.025+0000] {taskinstance.py:1516} INFO - Exporting the following env vars:
AIRFLOW_CTX_DAG_OWNER=***
AIRFLOW_CTX_DAG_ID=data_extraction_dag
AIRFLOW_CTX_TASK_ID=upload_positions_to_gcs
AIRFLOW_CTX_EXECUTION_DATE=2023-04-12T09:16:47.753380+00:00
AIRFLOW_CTX_TRY_NUMBER=6
AIRFLOW_CTX_DAG_RUN_ID=manual__2023-04-12T09:16:47.753380+00:00
[2023-04-12T09:28:44.028+0000] {subprocess.py:63} INFO - Tmp dir root location: 
 /tmp
[2023-04-12T09:28:44.031+0000] {subprocess.py:75} INFO - Running command: ['/bin/bash', '-c', 'gsutil cp -r /opt/***/csv gs://nfl-data-lake_nfl-de-project/nfl_csv']
[2023-04-12T09:28:44.053+0000] {subprocess.py:86} INFO - Output:
[2023-04-12T09:28:44.341+0000] {taskinstance.py:1080} INFO - Dependencies not met for <TaskInstance: data_extraction_dag.upload_positions_to_gcs manual__2023-04-12T09:16:47.753380+00:00 [running]>, dependency 'Task Instance State' FAILED: Task is in the 'running' state.
[2023-04-12T09:28:44.350+0000] {taskinstance.py:1080} INFO - Dependencies not met for <TaskInstance: data_extraction_dag.upload_positions_to_gcs manual__2023-04-12T09:16:47.753380+00:00 [running]>, dependency 'Task Instance Not Running' FAILED: Task is in the running state
[2023-04-12T09:28:44.354+0000] {local_task_job.py:151} INFO - Task is not able to be run
[2023-04-12T09:28:48.883+0000] {subprocess.py:93} INFO - ServiceException: 401 Anonymous caller does not have storage.objects.list access to the Google Cloud Storage bucket. Permission 'storage.objects.list' denied on resource (or it may not exist).
[2023-04-12T09:28:49.311+0000] {subprocess.py:97} INFO - Command exited with return code 1
[2023-04-12T09:28:49.323+0000] {taskinstance.py:1776} ERROR - Task failed with exception
Traceback (most recent call last):
  File "/home/airflow/.local/lib/python3.9/site-packages/airflow/decorators/base.py", line 217, in execute
    return_value = super().execute(context)
  File "/home/airflow/.local/lib/python3.9/site-packages/airflow/operators/python.py", line 175, in execute
    return_value = self.execute_callable()
  File "/home/airflow/.local/lib/python3.9/site-packages/airflow/operators/python.py", line 192, in execute_callable
    return self.python_callable(*self.op_args, **self.op_kwargs)
  File "/opt/airflow/dags/data_ingestion.py", line 157, in upload_positions_to_gcs
    operator.execute(context={})
  File "/home/airflow/.local/lib/python3.9/site-packages/airflow/operators/bash.py", line 196, in execute
    raise AirflowException(
airflow.exceptions.AirflowException: Bash command failed. The command returned a non-zero exit code 1.
[2023-04-12T09:28:49.334+0000] {taskinstance.py:1327} INFO - Marking task as UP_FOR_RETRY. dag_id=data_extraction_dag, task_id=upload_positions_to_gcs, execution_date=20230412T091647, start_date=20230412T092843, end_date=20230412T092849
[2023-04-12T09:28:49.353+0000] {standard_task_runner.py:100} ERROR - Failed to execute job 707 for task upload_positions_to_gcs (Bash command failed. The command returned a non-zero exit code 1.; 5979)
[2023-04-12T09:28:49.400+0000] {local_task_job.py:212} INFO - Task exited with return code 1
[2023-04-12T09:28:49.415+0000] {taskinstance.py:2596} INFO - 0 downstream tasks scheduled from follow-on schedule check
