[2023-04-12T05:07:01.136+0000] {taskinstance.py:1090} INFO - Dependencies all met for dep_context=non-requeueable deps ti=<TaskInstance: data_extraction_dag.load_to_gcs manual__2023-04-12T05:01:00.202303+00:00 [queued]>
[2023-04-12T05:07:01.147+0000] {taskinstance.py:1090} INFO - Dependencies all met for dep_context=requeueable deps ti=<TaskInstance: data_extraction_dag.load_to_gcs manual__2023-04-12T05:01:00.202303+00:00 [queued]>
[2023-04-12T05:07:01.148+0000] {taskinstance.py:1288} INFO - 
--------------------------------------------------------------------------------
[2023-04-12T05:07:01.149+0000] {taskinstance.py:1289} INFO - Starting attempt 2 of 2
[2023-04-12T05:07:01.150+0000] {taskinstance.py:1290} INFO - 
--------------------------------------------------------------------------------
[2023-04-12T05:07:01.167+0000] {taskinstance.py:1309} INFO - Executing <Task(_PythonDecoratedOperator): load_to_gcs> on 2023-04-12 05:01:00.202303+00:00
[2023-04-12T05:07:01.179+0000] {standard_task_runner.py:55} INFO - Started process 283 to run task
[2023-04-12T05:07:01.184+0000] {standard_task_runner.py:82} INFO - Running: ['***', 'tasks', 'run', 'data_extraction_dag', 'load_to_gcs', 'manual__2023-04-12T05:01:00.202303+00:00', '--job-id', '356', '--raw', '--subdir', 'DAGS_FOLDER/data_ingestion.py', '--cfg-path', '/tmp/tmpsqsx8kyx']
[2023-04-12T05:07:01.187+0000] {standard_task_runner.py:83} INFO - Job 356: Subtask load_to_gcs
[2023-04-12T05:07:01.271+0000] {task_command.py:389} INFO - Running <TaskInstance: data_extraction_dag.load_to_gcs manual__2023-04-12T05:01:00.202303+00:00 [running]> on host 392d142fd52f
[2023-04-12T05:07:01.361+0000] {taskinstance.py:1516} INFO - Exporting the following env vars:
AIRFLOW_CTX_DAG_OWNER=***
AIRFLOW_CTX_DAG_ID=data_extraction_dag
AIRFLOW_CTX_TASK_ID=load_to_gcs
AIRFLOW_CTX_EXECUTION_DATE=2023-04-12T05:01:00.202303+00:00
AIRFLOW_CTX_TRY_NUMBER=2
AIRFLOW_CTX_DAG_RUN_ID=manual__2023-04-12T05:01:00.202303+00:00
[2023-04-12T05:07:01.374+0000] {taskinstance.py:1776} ERROR - Task failed with exception
Traceback (most recent call last):
  File "/home/airflow/.local/lib/python3.9/site-packages/airflow/decorators/base.py", line 217, in execute
    return_value = super().execute(context)
  File "/home/airflow/.local/lib/python3.9/site-packages/airflow/operators/python.py", line 175, in execute
    return_value = self.execute_callable()
  File "/home/airflow/.local/lib/python3.9/site-packages/airflow/operators/python.py", line 192, in execute_callable
    return self.python_callable(*self.op_args, **self.op_kwargs)
  File "/opt/airflow/dags/data_ingestion.py", line 145, in load_to_gcs
    athletes_df=task_athlete_stats(athlete_ids)
  File "/home/airflow/.local/lib/python3.9/site-packages/airflow/decorators/base.py", line 311, in __call__
    op = self.operator_class(
  File "/home/airflow/.local/lib/python3.9/site-packages/airflow/models/baseoperator.py", line 402, in apply_defaults
    self.set_xcomargs_dependencies()
  File "/home/airflow/.local/lib/python3.9/site-packages/airflow/models/baseoperator.py", line 1098, in set_xcomargs_dependencies
    XComArg.apply_upstream_relationship(self, arg)
  File "/home/airflow/.local/lib/python3.9/site-packages/airflow/models/xcom_arg.py", line 122, in apply_upstream_relationship
    op.set_upstream(operator)
  File "/home/airflow/.local/lib/python3.9/site-packages/airflow/models/taskmixin.py", line 244, in set_upstream
    self._set_relatives(task_or_task_list, upstream=True, edge_modifier=edge_modifier)
  File "/home/airflow/.local/lib/python3.9/site-packages/airflow/models/taskmixin.py", line 199, in _set_relatives
    raise AirflowException(
airflow.exceptions.AirflowException: Tried to create relationships between tasks that don't have DAGs yet. Set the DAG for at least one task and try again: [<Task(_PythonDecoratedOperator): task_athlete_stats>, <Task(_PythonDecoratedOperator): task_athlete_ids>]
[2023-04-12T05:07:01.387+0000] {taskinstance.py:1327} INFO - Marking task as FAILED. dag_id=data_extraction_dag, task_id=load_to_gcs, execution_date=20230412T050100, start_date=20230412T050701, end_date=20230412T050701
[2023-04-12T05:07:01.403+0000] {standard_task_runner.py:100} ERROR - Failed to execute job 356 for task load_to_gcs (Tried to create relationships between tasks that don't have DAGs yet. Set the DAG for at least one task and try again: [<Task(_PythonDecoratedOperator): task_athlete_stats>, <Task(_PythonDecoratedOperator): task_athlete_ids>]; 283)
[2023-04-12T05:07:01.436+0000] {local_task_job.py:212} INFO - Task exited with return code 1
[2023-04-12T05:07:01.454+0000] {taskinstance.py:2596} INFO - 0 downstream tasks scheduled from follow-on schedule check
