[2023-04-12T06:33:53.604+0000] {taskinstance.py:1080} INFO - Dependencies not met for <TaskInstance: data_extraction_dag.load_to_gcs manual__2023-04-12T05:46:33.697967+00:00 [failed]>, dependency 'Task Instance State' FAILED: Task is in the 'failed' state.
[2023-04-12T06:33:53.617+0000] {local_task_job.py:151} INFO - Task is not able to be run
[2023-04-12T06:34:13.966+0000] {taskinstance.py:1090} INFO - Dependencies all met for dep_context=non-requeueable deps ti=<TaskInstance: data_extraction_dag.load_to_gcs manual__2023-04-12T05:46:33.697967+00:00 [queued]>
[2023-04-12T06:34:13.982+0000] {taskinstance.py:1090} INFO - Dependencies all met for dep_context=requeueable deps ti=<TaskInstance: data_extraction_dag.load_to_gcs manual__2023-04-12T05:46:33.697967+00:00 [queued]>
[2023-04-12T06:34:13.982+0000] {taskinstance.py:1288} INFO - 
--------------------------------------------------------------------------------
[2023-04-12T06:34:13.984+0000] {taskinstance.py:1289} INFO - Starting attempt 11 of 12
[2023-04-12T06:34:13.985+0000] {taskinstance.py:1290} INFO - 
--------------------------------------------------------------------------------
[2023-04-12T06:34:14.005+0000] {taskinstance.py:1309} INFO - Executing <Task(_PythonDecoratedOperator): load_to_gcs> on 2023-04-12 05:46:33.697967+00:00
[2023-04-12T06:34:14.018+0000] {standard_task_runner.py:55} INFO - Started process 1934 to run task
[2023-04-12T06:34:14.021+0000] {standard_task_runner.py:82} INFO - Running: ['***', 'tasks', 'run', 'data_extraction_dag', 'load_to_gcs', 'manual__2023-04-12T05:46:33.697967+00:00', '--job-id', '456', '--raw', '--subdir', 'DAGS_FOLDER/data_ingestion.py', '--cfg-path', '/tmp/tmpw_mxi2e6']
[2023-04-12T06:34:14.025+0000] {standard_task_runner.py:83} INFO - Job 456: Subtask load_to_gcs
[2023-04-12T06:34:14.103+0000] {task_command.py:389} INFO - Running <TaskInstance: data_extraction_dag.load_to_gcs manual__2023-04-12T05:46:33.697967+00:00 [running]> on host a073412e57f0
[2023-04-12T06:34:14.250+0000] {taskinstance.py:1516} INFO - Exporting the following env vars:
AIRFLOW_CTX_DAG_OWNER=***
AIRFLOW_CTX_DAG_ID=data_extraction_dag
AIRFLOW_CTX_TASK_ID=load_to_gcs
AIRFLOW_CTX_EXECUTION_DATE=2023-04-12T05:46:33.697967+00:00
AIRFLOW_CTX_TRY_NUMBER=11
AIRFLOW_CTX_DAG_RUN_ID=manual__2023-04-12T05:46:33.697967+00:00
[2023-04-12T06:34:14.254+0000] {logging_mixin.py:137} INFO - Loading for nfl data to parquet started
[2023-04-12T06:34:14.299+0000] {taskinstance.py:1776} ERROR - Task failed with exception
Traceback (most recent call last):
  File "/home/airflow/.local/lib/python3.9/site-packages/airflow/decorators/base.py", line 217, in execute
    return_value = super().execute(context)
  File "/home/airflow/.local/lib/python3.9/site-packages/airflow/operators/python.py", line 175, in execute
    return_value = self.execute_callable()
  File "/home/airflow/.local/lib/python3.9/site-packages/airflow/operators/python.py", line 192, in execute_callable
    return self.python_callable(*self.op_args, **self.op_kwargs)
  File "/opt/airflow/dags/data_ingestion.py", line 150, in load_to_gcs
    df.to_parquet(f'{path}/nfl_parquets/{year}/{season_type}/{filename}_parquet', engine='pyarrow')
  File "/home/airflow/.local/lib/python3.9/site-packages/pandas/util/_decorators.py", line 211, in wrapper
    return func(*args, **kwargs)
  File "/home/airflow/.local/lib/python3.9/site-packages/pandas/core/frame.py", line 2976, in to_parquet
    return to_parquet(
  File "/home/airflow/.local/lib/python3.9/site-packages/pandas/io/parquet.py", line 430, in to_parquet
    impl.write(
  File "/home/airflow/.local/lib/python3.9/site-packages/pandas/io/parquet.py", line 174, in write
    table = self.api.Table.from_pandas(df, **from_pandas_kwargs)
  File "pyarrow/table.pxi", line 3475, in pyarrow.lib.Table.from_pandas
  File "/home/airflow/.local/lib/python3.9/site-packages/pyarrow/pandas_compat.py", line 611, in dataframe_to_arrays
    arrays = [convert_column(c, f)
  File "/home/airflow/.local/lib/python3.9/site-packages/pyarrow/pandas_compat.py", line 611, in <listcomp>
    arrays = [convert_column(c, f)
  File "/home/airflow/.local/lib/python3.9/site-packages/pyarrow/pandas_compat.py", line 598, in convert_column
    raise e
  File "/home/airflow/.local/lib/python3.9/site-packages/pyarrow/pandas_compat.py", line 592, in convert_column
    result = pa.array(col, type=type_, from_pandas=True, safe=safe)
  File "pyarrow/array.pxi", line 316, in pyarrow.lib.array
  File "pyarrow/array.pxi", line 83, in pyarrow.lib._ndarray_to_array
  File "pyarrow/error.pxi", line 123, in pyarrow.lib.check_status
pyarrow.lib.ArrowTypeError: ("Expected bytes, got a 'int' object", 'Conversion failed for column name with type object')
[2023-04-12T06:34:14.334+0000] {taskinstance.py:1327} INFO - Marking task as UP_FOR_RETRY. dag_id=data_extraction_dag, task_id=load_to_gcs, execution_date=20230412T054633, start_date=20230412T063413, end_date=20230412T063414
[2023-04-12T06:34:14.355+0000] {standard_task_runner.py:100} ERROR - Failed to execute job 456 for task load_to_gcs (("Expected bytes, got a 'int' object", 'Conversion failed for column name with type object'); 1934)
[2023-04-12T06:34:14.395+0000] {local_task_job.py:212} INFO - Task exited with return code 1
[2023-04-12T06:34:14.415+0000] {taskinstance.py:2596} INFO - 0 downstream tasks scheduled from follow-on schedule check
